
 Executando: C:\Users\Danilo\OneDrive\Área de Trabalho\Revisor de texto\Edição separada\revisor final\dossel_project\venv\scripts\python.exe Scripts\Mapeador_Completo.py documento_teste_erros (1)_fPGuMdj.docx
 Erro ao executar 'Scripts\Mapeador_Completo.py' para 'documento_teste_erros (1)_fPGuMdj.docx'.
   Saída: Traceback (most recent call last):
  File "C:\Users\Danilo\OneDrive\rea de Trabalho\Revisor de texto\Edio separada\revisor final\dossel_project\Scripts\Mapeador_Completo.py", line 48, in <module>
    django.setup()                     # inicializa o Django fora do manage.py
    ~~~~~~~~~~~~^^
  File "C:\Users\Danilo\OneDrive\rea de Trabalho\Revisor de texto\Edio separada\revisor final\dossel_project\venv\Lib\site-packages\django\__init__.py", line 19, in setup
    configure_logging(settings.LOGGING_CONFIG, settings.LOGGING)
                      ^^^^^^^^^^^^^^^^^^^^^^^
  File "C:\Users\Danilo\OneDrive\rea de Trabalho\Revisor de texto\Edio separada\revisor final\dossel_project\venv\Lib\site-packages\django\conf\__init__.py", line 81, in __getattr__
    self._setup(name)
    ~~~~~~~~~~~^^^^^^
  File "C:\Users\Danilo\OneDrive\rea de Trabalho\Revisor de texto\Edio separada\revisor final\dossel_project\venv\Lib\site-packages\django\conf\__init__.py", line 68, in _setup
    self._wrapped = Settings(settings_module)
                    ~~~~~~~~^^^^^^^^^^^^^^^^^
  File "C:\Users\Danilo\OneDrive\rea de Trabalho\Revisor de texto\Edio separada\revisor final\dossel_project\venv\Lib\site-packages\django\conf\__init__.py", line 166, in __init__
    mod = importlib.import_module(self.SETTINGS_MODULE)
  File "C:\Users\Danilo\AppData\Local\Programs\Python\Python313\Lib\importlib\__init__.py", line 88, in import_module
    return _bootstrap._gcd_import(name[level:], package, level)
           ~~~~~~~~~~~~~~~~~~~~~~^^^^^^^^^^^^^^^^^^^^^^^^^^^^^^
  File "<frozen importlib._bootstrap>", line 1387, in _gcd_import
  File "<frozen importlib._bootstrap>", line 1360, in _find_and_load
  File "<frozen importlib._bootstrap>", line 1310, in _find_and_load_unlocked
  File "<frozen importlib._bootstrap>", line 488, in _call_with_frames_removed
  File "<frozen importlib._bootstrap>", line 1387, in _gcd_import
  File "<frozen importlib._bootstrap>", line 1360, in _find_and_load
  File "<frozen importlib._bootstrap>", line 1324, in _find_and_load_unlocked
ModuleNotFoundError: No module named 'dossel_project'

--- GERENCIADOR INICIADO COM SUCESSO ---
 Arquivo 'documento_teste_erros (1)_fPGuMdj.docx' copiado para a pasta 'C:\Users\Danilo\OneDrive\Área de Trabalho\Revisor de texto\Edição separada\revisor final\dossel_project\media\entrada'.

 Documento a processar: ['documento_teste_erros (1)_fPGuMdj.docx']
 Modo de revisão: completa
 E-mail destino: n.danilo@dosselambiental.com.br
 Progresso atualizado para: 5% (ID da Revisão: 9)

 Iniciando processamento paralelo de 'Scripts\Mapeador_Completo.py' para 1 documento(s).
 Houve falhas durante o processamento paralelo de 'Scripts\Mapeador_Completo.py'.
 Falhas durante o processamento.
 Progresso atualizado para: 100% (ID da Revisão: 9)
 Gerenciador finalizou a execução.
